Workbook

Sheet Financials
A1: Adani Enterprises Ltd: Income Statement
A2: Actuals from Screener.in Data Sheet (uploaded file). Forecast driven by Assumptions.
A4: ₹ Crore, FYE 31 March | B4: FY17 | C4: FY18 | D4: FY19 | E4: FY20 | F4: FY21 | G4: FY22 | H4: FY23 | I4: FY24 | J4: FY25 | K4: FY26 | L4: FY27E | M4: FY28E | N4: FY29E | O4: FY30E | P4: FY31E
A5: Sales | B5: 36532.86 | C5: 35923.92 | D5: 40378.66 | E5: 43402.56 | F5: 39537.13 | G5: 69420.18 | H5: 127539.5 | I5: 96420.98 | J5: 97894.75 | K5: 100468.61 | L5: =Financials!K5*(1+Assumptions!L5) -> 105492.04 | M5: =Financials!L5*(1+Assumptions!M5) -> 111821.56 | N5: =Financials!M5*(1+Assumptions!N5) -> 119649.07 | O5: =Financials!N5*(1+Assumptions!O5) -> 128024.51 | P5: =Financials!O5*(1+Assumptions!P5) -> 136986.22
A6: Sales growth % | C6: =Financials!C5/Financials!B5-1 -> -0.016668282 | D6: =Financials!D5/Financials!C5-1 -> 0.12400484 | E6: =Financials!E5/Financials!D5-1 -> 0.074888567 | F6: =Financials!F5/Financials!E5-1 -> -0.089059954 | G6: =Financials!G5/Financials!F5-1 -> 0.75582244 | H6: =Financials!H5/Financials!G5-1 -> 0.83721074 | I6: =Financials!I5/Financials!H5-1 -> -0.24399123 | J6: =Financials!J5/Financials!I5-1 -> 0.015284744 | ... P6: =Financials!P5/Financials!O5-1 -> 0.07
A7: Raw material cost | B7: 30945.16 | C7: 30771.08 | D7: 33821.4 | E7: 34350.2 | F7: 29791.08 | G7: 57651.32 | H7: 93814.06 | I7: 51507.72 | J7: 49524.73 | K7: 56933.41 | L7: =Financials!L5*Assumptions!L6 -> 56860.21 | M7: =Financials!M5*Assumptions!M6 -> 60271.822 | N7: =Financials!N5*Assumptions!N6 -> 64490.85 | O7: =Financials!O5*Assumptions!O6 -> 69005.209 | P7: =Financials!P5*Assumptions!P6 -> 73835.574
A8: Change in inventory (subtracted) | B8: -36.38 | C8: 772.74 | D8: 499.99 | E8: -310.13 | F8: -456.74 | G8: 3933.82 | H8: 327.16 | I8: 1116.49 | J8: -1844.54 | K8: 2824.59 | L8: 0 | M8: 0 | N8: 0 | O8: 0 | P8: 0
A9: Power & fuel | B9: 7.42 | C9: 2.91 | D9: 5.74 | E9: 12.22 | F9: 13.4 | G9: 58.98 | H9: 18.42 | I9: 26.46 | J9: 2037.48 | K9: 2142.7 | L9: =Financials!L5*Assumptions!L7 -> 2215.3329 | M9: =Financials!M5*Assumptions!M7 -> 2348.2528 | N9: =Financials!N5*Assumptions!N7 -> 2512.6305 | O9: =Financials!O5*Assumptions!O7 -> 2688.5147 | P9: =Financials!P5*Assumptions!P7 -> 2876.7107
A10: Other manufacturing expenses | B10: 1910.37 | C10: 2204.89 | D10: 2551.28 | E10: 3115.25 | F10: 4357.88 | G10: 7793.57 | H10: 14377.83 | I10: 22793.04 | J10: 16964.51 | K10: 15610.12 | L10: =Financials!L5*Assumptions!L8 -> 16456.758 | M10: =Financials!M5*Assumptions!M8 -> 17444.164 | N10: =Financials!N5*Assumptions!N8 -> 18665.255 | O10: =Financials!O5*Assumptions!O8 -> 19971.823 | P10: =Financials!P5*Assumptions!P8 -> 21369.851
A11: Employee cost | B11: 511.48 | C11: 568.97 | D11: 657.18 | E11: 683.28 | F11: 830.36 | G11: 1182.1 | H11: 1879.07 | I11: 2332.96 | J11: 3121.84 | K11: 3661.56 | L11: =Financials!L5*Assumptions!L9 -> 3797.7135 | M11: =Financials!M5*Assumptions!M9 -> 4025.5763 | N11: =Financials!N5*Assumptions!N9 -> 4307.3666 | O11: =Financials!O5*Assumptions!O9 -> 4608.8823 | P11: =Financials!P5*Assumptions!P9 -> 4931.504
A12: Selling & administration | B12: 1004.69 | C12: 928.28 | D12: 1230.62 | E12: 1954.57 | F12: 1306.48 | G12: 2412.38 | H12: 8135.29 | I12: 8272.86 | J12: 9245.98 | K12: 9817.24 | L12: =Financials!L5*Assumptions!L10 -> 10338.22 | M12: =Financials!M5*Assumptions!M10 -> 10958.513 | N12: =Financials!N5*Assumptions!N10 -> 11725.609 | O12: =Financials!O5*Assumptions!O10 -> 12546.402 | P12: =Financials!P5*Assumptions!P10 -> 13424.65
A13: Other expenses | B13: 215.13 | C13: 182.82 | D13: 643.09 | E13: 682.52 | F13: 275.54 | G13: 542.05 | H13: 824.3 | I13: 1227.83 | J13: 903.64 | K13: 1137.39 | L13: =Financials!L5*Assumptions!L11 -> 1160.4124 | M13: =Financials!M5*Assumptions!M11 -> 1230.0372 | N13: =Financials!N5*Assumptions!N11 -> 1316.1398 | O13: =Financials!O5*Assumptions!O11 -> 1408.2696 | P13: =Financials!P5*Assumptions!P11 -> 1506.8485
A14: Total operating expenses | B14: =Financials!B7+Financials!B9+Financials!B10+Financials!B11+Financials!B12+Financials!B13-Financials!B8 -> 34630.63 | C14: =Financials!C7+Financials!C9+Financials!C10+Financials!C11+Financials!C12+Financials!C13-Financials!C8 -> 33886.21 | D14: =Financials!D7+Financials!D9+Financials!D10+Financials!D11+Financials!D12+Financials!D13-Financials!D8 -> 38409.32 | E14: =Financials!E7+Financials!E9+Financials!E10+Financials!E11+Financials!E12+Financials!E13-Financials!E8 -> 41108.17 | F14: =Financials!F7+Financials!F9+Financials!F10+Financials!F11+Financials!F12+Financials!F13-Financials!F8 -> 37031.48 | G14: =Financials!G7+Financials!G9+Financials!G10+Financials!G11+Financials!G12+Financials!G13-Financials!G8 -> 65706.58 | H14: =Financials!H7+Financials!H9+Financials!H10+Financials!H11+Financials!H12+Financials!H13-Financials!H8 -> 118721.81 | I14: =Financials!I7+Financials!I9+Financials!I10+Financials!I11+Financials!I12+Financials!I13-Financials!I8 -> 85044.38 | ... P14: =Financials!P7+Financials!P9+Financials!P10+Financials!P11+Financials!P12+Financials!P13-Financials!P8 -> 117945.14
A15: Operating profit (EBITDA) | B15: =Financials!B5-Financials!B14 -> 1902.23 | C15: =Financials!C5-Financials!C14 -> 2037.71 | D15: =Financials!D5-Financials!D14 -> 1969.34 | E15: =Financials!E5-Financials!E14 -> 2294.39 | F15: =Financials!F5-Financials!F14 -> 2505.65 | G15: =Financials!G5-Financials!G14 -> 3713.6 | H15: =Financials!H5-Financials!H14 -> 8817.69 | I15: =Financials!I5-Financials!I14 -> 11376.6 | ... P15: =Financials!P5-Financials!P14 -> 19041.085
A16: EBITDA margin % | B16: =Financials!B15/Financials!B5 -> 0.052069014 | C16: =Financials!C15/Financials!C5 -> 0.05672293 | D16: =Financials!D15/Financials!D5 -> 0.048771802 | E16: =Financials!E15/Financials!E5 -> 0.052863011 | F16: =Financials!F15/Financials!F5 -> 0.063374605 | G16: =Financials!G15/Financials!G5 -> 0.053494531 | H16: =Financials!H15/Financials!H5 -> 0.069136934 | I16: =Financials!I15/Financials!I5 -> 0.11798884 | ... P16: =Financials!P15/Financials!P5 -> 0.139
A17: Other income | B17: 749.41 | C17: 363.21 | D17: 504.22 | E17: 872.32 | F17: 494.31 | G17: 1012.11 | H17: 834.23 | I17: 1146.39 | J17: 6403.1 | K17: 11688.34 | L17: =Financials!L5*Assumptions!L12 -> 5274.602 | M17: =Financials!M5*Assumptions!M12 -> 5591.0781 | N17: =Financials!N5*Assumptions!N12 -> 5982.4536 | O17: =Financials!O5*Assumptions!O12 -> 6401.2254 | P17: =Financials!P5*Assumptions!P12 -> 6849.3111
A18: Depreciation | B18: 315.46 | C18: 663.92 | D18: 389.77 | E18: 472.06 | F18: 537.14 | G18: 1247.78 | H18: 2436.14 | I18: 3042.15 | J18: 4211.33 | K18: 6135.34 | L18: =Financials!K53*Assumptions!L13 -> 9098.731 | M18: =Financials!L53*Assumptions!M13 -> 10463.399 | N18: =Financials!M53*Assumptions!N13 -> 11845.266 | O18: =Financials!N53*Assumptions!O13 -> 13272.56 | P18: =Financials!O53*Assumptions!P13 -> 14752.511
A19: EBIT (after depreciation) | B19: =Financials!B15-Financials!B18 -> 1586.77 | C19: =Financials!C15-Financials!C18 -> 1373.79 | D19: =Financials!D15-Financials!D18 -> 1579.57 | E19: =Financials!E15-Financials!E18 -> 1822.33 | F19: =Financials!F15-Financials!F18 -> 1968.51 | G19: =Financials!G15-Financials!G18 -> 2465.82 | H19: =Financials!H15-Financials!H18 -> 6381.55 | I19: =Financials!I15-Financials!I18 -> 8334.45 | ... P19: =Financials!P15-Financials!P18 -> 4288.5736
A20: Interest | B20: 1257.31 | C20: 1250.17 | D20: 1625.07 | E20: 1572.32 | F20: 1376.85 | G20: 2525.88 | H20: 3968.9 | I20: 4554.7 | J20: 5978.02 | K20: 6019.12 | L20: =Financials!K49*Assumptions!L14 -> 7037.0381 | M20: =Financials!L49*Assumptions!M14 -> 8687.0381 | N20: =Financials!M49*Assumptions!N14 -> 10337.038 | O20: =Financials!N49*Assumptions!O14 -> 11657.038 | P20: =Financials!O49*Assumptions!P14 -> 12647.038
A21: Profit before tax | B21: =Financials!B19+Financials!B17-Financials!B20 -> 1078.87 | C21: =Financials!C19+Financials!C17-Financials!C20 -> 486.83 | D21: =Financials!D19+Financials!D17-Financials!D20 -> 458.72 | E21: =Financials!E19+Financials!E17-Financials!E20 -> 1122.33 | F21: =Financials!F19+Financials!F17-Financials!F20 -> 1085.97 | G21: =Financials!G19+Financials!G17-Financials!G20 -> 952.05 | H21: =Financials!H19+Financials!H17-Financials!H20 -> 3246.88 | I21: =Financials!I19+Financials!I17-Financials!I20 -> 4926.14 | ... P21: =Financials!P19+Financials!P17-Financials!P20 -> -1509.1533
A22: Tax | B22: 271.15 | C22: 112.11 | D22: 144.54 | E22: 324.33 | F22: 339.65 | G22: 476.68 | H22: 1037.94 | I22: 1631.51 | J22: 2968.52 | K22: 3831.15 | L22: =Financials!L21*Assumptions!L15 -> 1076.0301 | M22: =Financials!M21*Assumptions!M15 -> 561.42621 | N22: =Financials!N21*Assumptions!N15 -> 122.07775 | O22: =Financials!O21*Assumptions!O15 -> -207.42931 | P22: =Financials!P21*Assumptions!P15 -> -427.0904
A23: Effective tax rate % | B23: =Financials!B22/Financials!B21 -> 0.25132778 | C23: =Financials!C22/Financials!C21 -> 0.23028573 | D23: =Financials!D22/Financials!D21 -> 0.31509418 | E23: =Financials!E22/Financials!E21 -> 0.28897918 | F23: =Financials!F22/Financials!F21 -> 0.31276186 | G23: =Financials!G22/Financials!G21 -> 0.50068799 | H23: =Financials!H22/Financials!H21 -> 0.31967304 | I23: =Financials!I22/Financials!I21 -> 0.3311944 | ... P23: =Financials!P22/Financials!P21 -> 0.283
A24: Profit after tax (consolidated) | B24: =Financials!B21-Financials!B22 -> 807.72 | C24: =Financials!C21-Financials!C22 -> 374.72 | D24: =Financials!D21-Financials!D22 -> 314.18 | E24: =Financials!E21-Financials!E22 -> 798 | F24: =Financials!F21-Financials!F22 -> 746.32 | G24: =Financials!G21-Financials!G22 -> 475.37 | H24: =Financials!H21-Financials!H22 -> 2208.94 | I24: =Financials!I21-Financials!I22 -> 3294.63 | ... P24: =Financials!P21-Financials!P22 -> -1082.063
A25: Minority interest & other (actuals derived) | B25: =Financials!B24-Financials!B26 -> -180.02 | C25: =Financials!C24-Financials!C26 -> -382.53 | D25: =Financials!D24-Financials!D26 -> -402.96 | E25: =Financials!E24-Financials!E26 -> -340.17 | F25: =Financials!F24-Financials!F26 -> -176.32 | G25: =Financials!G24-Financials!G26 -> -301.19 | H25: =Financials!H24-Financials!H26 -> -255.04 | I25: =Financials!I24-Financials!I26 -> 55.08 | ... K25: =Financials!K24-Financials!K26 -> 354.04 | L25: =Financials!L24*Assumptions!L16 -> 100.86927 | M25: =Financials!M24*Assumptions!M16 -> 52.629244 | N25: =Financials!N24*Assumptions!N16 -> 11.443819 | O25: =Financials!O24*Assumptions!O16 -> -19.444849 | P25: =Financials!P24*Assumptions!P16 -> -40.036329
A26: Net profit attributable to shareholders | B26: 987.74 | C26: 757.25 | D26: 717.14 | E26: 1138.17 | F26: 922.64 | G26: 776.56 | H26: 2463.98 | I26: 3239.55 | J26: 7111.96 | K26: 9339.47 | L26: =Financials!L24-Financials!L25 -> 2625.3272 | M26: =Financials!M24-Financials!M25 -> 1369.7828 | N26: =Financials!N24-Financials!N25 -> 297.84858 | O26: =Financials!O24-Financials!O25 -> -506.0916 | P26: =Financials!P24-Financials!P25 -> -1042.0266
A27: Dividends | B27: 43.99 | C27: 43.99 | D27: 43.99 | E27: 109.98 | F27: 109.98 | G27: 109.98 | H27: 136.8 | I27: 148.2 | J27: 150.05 | K27: 168.01 | L27: =Financials!L26*Assumptions!L17 -> 52.506543 | M27: =Financials!M26*Assumptions!M17 -> 27.395655 | N27: =Financials!N26*Assumptions!N17 -> 5.9569715 | O27: =Financials!O26*Assumptions!O17 -> -10.121832 | P27: =Financials!P26*Assumptions!P17 -> -20.840532
A28: Shares outstanding (Cr, adjusted) | B28: 123.18 | C28: 123.18 | D28: 123.18 | E28: 123.18 | F28: 123.18 | G28: 123.18 | H28: 127.68 | I28: 127.68 | J28: 129.27 | K28: 129.16 | L28: =Financials!K28 -> 129.16 | M28: =Financials!L28 -> 129.16 | N28: =Financials!M28 -> 129.16 | O28: =Financials!N28 -> 129.16 | P28: =Financials!O28 -> 129.16
A29: EPS (₹) | B29: =Financials!B26/Financials!B28 -> 8.0186719 | C29: =Financials!C26/Financials!C28 -> 6.1475077 | D29: =Financials!D26/Financials!D28 -> 5.8218867 | E29: =Financials!E26/Financials!E28 -> 9.2398928 | F29: =Financials!F26/Financials!F28 -> 7.490177 | G29: =Financials!G26/Financials!G28 -> 6.3042702 | H29: =Financials!H26/Financials!H28 -> 19.298089 | I29: =Financials!I26/Financials!I28 -> 25.372415 | ... P29: =Financials!P26/Financials!P28 -> -8.0677193
A43: BALANCE SHEET | B43: FY17 | C43: FY18 | D43: FY19 | E43: FY20 | F43: FY21 | G43: FY22 | H43: FY23 | I43: FY24 | J43: FY25 | K43: FY26 | L43: FY27E | M43: FY28E | N43: FY29E | O43: FY30E | P43: FY31E
A45: Equity share capital | B45: 109.98 | C45: 109.98 | D45: 109.98 | E45: 109.98 | F45: 109.98 | G45: 109.98 | H45: 114 | I45: 114 | J45: 115.42 | K45: 129.24 | L45: =Financials!K45 -> 129.24 | M45: =Financials!L45 -> 129.24 | N45: =Financials!M45 -> 129.24 | O45: =Financials!N45 -> 129.24 | P45: =Financials!O45 -> 129.24
A46: Reserves | B46: 14025.99 | C46: 14979.19 | D46: 14645.96 | E46: 16836.59 | F46: 17048.59 | G46: 22146.53 | H46: 32937.01 | I46: 38962.09 | J46: 50198.55 | K46: 80796.71 | L46: =Financials!K46+Financials!L26-Financials!L27 -> 83369.531 | M46: =Financials!L46+Financials!M26-Financials!M27 -> 84711.918 | N46: =Financials!M46+Financials!N26-Financials!N27 -> 85003.809 | O46: =Financials!N46+Financials!O26-Financials!O27 -> 84507.84 | P46: =Financials!O46+Financials!P26-Financials!P27 -> 83486.653
A47: Net worth (shareholders' equity) | B47: =Financials!B45+Financials!B46 -> 14135.97 | C47: =Financials!C45+Financials!C46 -> 15089.17 | D47: =Financials!D45+Financials!D46 -> 14755.94 | E47: =Financials!E45+Financials!E46 -> 16946.57 | F47: =Financials!F45+Financials!F46 -> 17158.57 | G47: =Financials!G45+Financials!G46 -> 22256.51 | H47: =Financials!H45+Financials!H46 -> 33051.01 | I47: =Financials!I45+Financials!I46 -> 39076.09 | ... P47: =Financials!P45+Financials!P46 -> 83615.893
A48: Minority interest (forecast accrual) | B48: 0 | C48: 0 | D48: 0 | E48: 0 | F48: 0 | G48: 0 | H48: 0 | I48: 0 | J48: 0 | K48: 0 | L48: =Financials!K48+Financials!L25 -> 100.86927 | M48: =Financials!L48+Financials!M25 -> 153.49851 | N48: =Financials!M48+Financials!N25 -> 164.94233 | O48: =Financials!N48+Financials!O25 -> 145.49748 | P48: =Financials!O48+Financials!P25 -> 105.46115
A49: Borrowings | B49: 20845.72 | C49: 17636.69 | D49: 11243.2 | E49: 12419.3 | F49: 16227.06 | G49: 41604.03 | H49: 53200.46 | I49: 65310.15 | J49: 91472.6 | K49: 106621.79 | L49: =Financials!K49+Assumptions!L19 -> 131621.79 | M49: =Financials!L49+Assumptions!M19 -> 156621.79 | N49: =Financials!M49+Assumptions!N19 -> 176621.79 | O49: =Financials!N49+Assumptions!O19 -> 191621.79 | P49: =Financials!O49+Assumptions!P19 -> 201621.79
A50: Other liabilities | B50: 12629.78 | C50: 23679.48 | D50: 16537.04 | E50: 17509.19 | F50: 18231.09 | G50: 37725.82 | H50: 55027.01 | I50: 56200 | J50: 56056.31 | K50: 73320.64 | L50: =Financials!L5*Assumptions!L23 -> 77009.19 | M50: =Financials!M5*Assumptions!M23 -> 81629.741 | N50: =Financials!N5*Assumptions!N23 -> 87343.823 | O50: =Financials!O5*Assumptions!O23 -> 93457.89 | P50: =Financials!P5*Assumptions!P23 -> 99999.943
A51: Total liabilities & equity | B51: =Financials!B47+Financials!B48+Financials!B49+Financials!B50 -> 47611.47 | C51: =Financials!C47+Financials!C48+Financials!C49+Financials!C50 -> 56405.34 | D51: =Financials!D47+Financials!D48+Financials!D49+Financials!D50 -> 42536.18 | E51: =Financials!E47+Financials!E48+Financials!E49+Financials!E50 -> 46875.06 | F51: =Financials!F47+Financials!F48+Financials!F49+Financials!F50 -> 51616.72 | G51: =Financials!G47+Financials!G48+Financials!G49+Financials!G50 -> 101586.36 | H51: =Financials!H47+Financials!H48+Financials!H49+Financials!H50 -> 141278.48 | I51: =Financials!I47+Financials!I48+Financials!I49+Financials!I50 -> 160586.24 | ... P51: =Financials!P47+Financials!P48+Financials!P49+Financials!P50 -> 385343.09
A53: Net block (fixed assets) | B53: 13667.98 | C53: 10555.19 | D53: 9020.11 | E53: 10476.46 | F53: 10837.61 | G53: 30122.77 | H53: 56881.13 | I53: 65978.3 | J53: 77260.14 | K53: 115173.81 | L53: =Financials!K53-Financials!L92-Financials!L18 -> 132448.09 | M53: =Financials!L53-Financials!M92-Financials!M18 -> 149940.08 | N53: =Financials!M53-Financials!N92-Financials!N18 -> 168007.08 | O53: =Financials!N53-Financials!O92-Financials!O18 -> 186740.65 | P53: =Financials!O53-Financials!P92-Financials!P18 -> 206234.69
A54: Capital work in progress | B54: 7731.49 | C54: 5525.87 | D54: 5764.92 | E54: 7346.73 | F54: 8825.46 | G54: 23544.42 | H54: 24025.21 | I54: 35179.5 | J54: 51515.81 | K54: 51753.42 | L54: =Financials!K54 -> 51753.42 | M54: =Financials!L54 -> 51753.42 | N54: =Financials!M54 -> 51753.42 | O54: =Financials!N54 -> 51753.42 | P54: =Financials!O54 -> 51753.42
A55: Investments | B55: 1041.75 | C55: 1460.72 | D55: 1511.35 | E55: 1952.49 | F55: 5502.94 | G55: 4292.21 | H55: 6310.17 | I55: 8700.69 | J55: 9886.61 | K55: 9428.37 | L55: =Financials!K55 -> 9428.37 | M55: =Financials!L55 -> 9428.37 | N55: =Financials!M55 -> 9428.37 | O55: =Financials!N55 -> 9428.37 | P55: =Financials!O55 -> 9428.37
A56: Receivables | B56: 12741.75 | C56: 12098.77 | D56: 14307.03 | E56: 13146.53 | F56: 11982.65 | G56: 13712.19 | H56: 12552.88 | I56: 9792.93 | J56: 9616.47 | K56: 12542.61 | L56: =Financials!L5*Assumptions!L20 -> 13186.505 | M56: =Financials!M5*Assumptions!M20 -> 13977.695 | N56: =Financials!N5*Assumptions!N20 -> 14956.134 | O56: =Financials!O5*Assumptions!O20 -> 16003.063 | P56: =Financials!P5*Assumptions!P20 -> 17123.278
...

Sheet Assumptions
A1: Adani Enterprises Ltd: Forecast Assumptions
A2: Blue = input (edit these). Black = formula. FY26 actual ratio shown in column K for reference.
A4: ₹ Crore, FYE 31 March | B4: FY17 | C4: FY18 | D4: FY19 | E4: FY20 | F4: FY21 | G4: FY22 | H4: FY23 | I4: FY24 | J4: FY25 | K4: FY26 | L4: FY27E | M4: FY28E | N4: FY29E | O4: FY30E | P4: FY31E
A5: Sales growth % | K5: =Financials!K6 -> 0.026292115 | L5: 0.05 | M5: 0.06 | N5: 0.07 | O5: 0.07 | P5: 0.07
A6: Raw material cost % sales | K6: =Financials!K7/Financials!K5 -> 0.56667859 | L6: 0.539 | M6: 0.539 | N6: 0.539 | O6: 0.539 | P6: 0.539
A7: Power & fuel % sales | K7: =Financials!K9/Financials!K5 -> 0.021327059 | L7: 0.021 | M7: 0.021 | N7: 0.021 | O7: 0.021 | P7: 0.021
A8: Other manufacturing exp % sales | K8: =Financials!K10/Financials!K5 -> 0.15537311 | L8: 0.156 | M8: 0.156 | N8: 0.156 | O8: 0.156 | P8: 0.156
A9: Employee cost % sales | K9: =Financials!K11/Financials!K5 -> 0.036444816 | L9: 0.036 | M9: 0.036 | N9: 0.036 | O9: 0.036 | P9: 0.036
A10: Selling & admin % sales | K10: =Financials!K12/Financials!K5 -> 0.0977145 | L10: 0.098 | M10: 0.098 | N10: 0.098 | O10: 0.098 | P10: 0.098
A11: Other expenses % sales | K11: =Financials!K13/Financials!K5 -> 0.011320849 | L11: 0.011 | M11: 0.011 | N11: 0.011 | O11: 0.011 | P11: 0.011
A12: Other income % sales | K12: =Financials!K17/Financials!K5 -> 0.11633823 | L12: 0.05 | M12: 0.05 | N12: 0.05 | O12: 0.05 | P12: 0.05
A13: Depreciation % opening net block | K13: =Financials!K18/Financials!J53 -> 0.079411453 | L13: 0.079 | M13: 0.079 | N13: 0.079 | O13: 0.079 | P13: 0.079
A14: Interest rate on opening borrowings | K14: =Financials!K20/Financials!J49 -> 0.065802437 | L14: 0.066 | M14: 0.066 | N14: 0.066 | O14: 0.066 | P14: 0.066
A15: Effective tax rate | K15: =Financials!K23 -> 0.28327145 | L15: 0.283 | M15: 0.283 | N15: 0.283 | O15: 0.283 | P15: 0.283
A16: Minority interest & other % of PAT | K16: =Financials!K25/Financials!K24 -> 0.036523406 | L16: 0.037 | M16: 0.037 | N16: 0.037 | O16: 0.037 | P16: 0.037
A17: Dividend payout % of attributable NP | K17: =Financials!K27/Financials!K26 -> 0.017989244 | L17: 0.02 | M17: 0.02 | N17: 0.02 | O17: 0.02 | P17: 0.02
A18: Capex % sales | K18: =(Financials!K53-Financials!J53+Financials!K18)/Financials!K5 -> 0.43843555 | L18: 0.25 | M18: 0.25 | N18: 0.25 | O18: 0.25 | P18: 0.25
A19: Net borrowing / (repayment) ₹ Cr | L19: 25000 | M19: 25000 | N19: 20000 | O19: 15000 | P19: 10000
A20: Receivables % sales | K20: =Financials!K56/Financials!K5 -> 0.12484108 | L20: 0.125 | M20: 0.125 | N20: 0.125 | O20: 0.125 | P20: 0.125
A21: Inventory % sales | K21: =Financials!K57/Financials!K5 -> 0.18625698 | L21: 0.186 | M21: 0.186 | N21: 0.186 | O21: 0.186 | P21: 0.186
A22: Other assets (residual) % sales | K22: =Financials!K59/Financials!K5 -> 0.41254448 | L22: 0.413 | M22: 0.413 | N22: 0.413 | O22: 0.413 | P22: 0.413
A23: Other liabilities % sales | K23: =Financials!K50/Financials!K5 -> 0.72978655 | L23: 0.73 | M23: 0.73 | N23: 0.73 | O23: 0.73 | P23: 0.73
A25: Model notes
A26: • Interest is charged on opening borrowings and depreciation on opening net block, so the model has no circular references.
A27: • CWIP and Investments are held flat. Capex is set as a % of sales and added to net block.
A28: • Cash is the balancing item through the cash flow statement. The balance check on BS must be zero in every year.
A29: • Other liabilities is the largest working-capital line; holding it at a % of sales drives much of the forecast cash build.

Sheet WACC
B1: Adani Enterprises Ltd: Weighted Average Cost of Capital (WACC)
B2: Inputs in blue. Feeds the DCF tab.
B4: Discount rate (WACC)
B5: Risk-free rate (10Y G-sec) | C5: 0.065
B6: Equity risk premium | C6: 0.07
B7: Levered beta | C7: 1.2
B8: Cost of equity (CAPM) | C8: =C5+C7*C6 -> 0.149
B9: Pre-tax cost of debt | C9: =Assumptions!L14 -> 0.066
B10: Tax rate | C10: =Assumptions!L15 -> 0.283
B11: After-tax cost of debt | C11: =C9*(1-C10) -> 0.047322
B12: Market value of equity | C12: 361216.96
B13: Debt (FY26 borrowings) | C13: =Financials!K49 -> 106621.79
B14: Equity weight | C14: =C12/(C12+C13) -> 0.77209714
B15: Debt weight | C15: =C13/(C12+C13) -> 0.22790286
B16: WACC | C16: =C14*C8+C15*C11 -> 0.12582729
B17: Terminal growth rate | C17: 0.05
B18: Return on new invested capital (terminal) | C18: 0.1

Sheet DCF
B1: Adani Enterprises Ltd: Discounted Cash Flow Valuation
B2: ₹ Crore unless stated. Valuation date 31-Mar-2026. Forecast from IS / BS / CF tabs. Blue = input.
B4: WACC, terminal growth and RONIC are on the WACC tab
B19: Unlevered free cash flow | C19: FY27E | D19: FY28E | E19: FY29E | F19: FY30E | G19: FY31E
B20: Sales | C20: =Financials!L5 -> 105492.04 | D20: =Financials!M5 -> 111821.56 | E20: =Financials!N5 -> 119649.07 | F20: =Financials!O5 -> 128024.51 | G20: =Financials!P5 -> 136986.22
B21: EBITDA | C21: =Financials!L15 -> 14663.394 | D21: =Financials!M15 -> 15543.197 | E21: =Financials!N15 -> 16631.221 | F21: =Financials!O15 -> 17795.407 | G21: =Financials!P15 -> 19041.085
B22: Add back: depreciation | C22: =Financials!L18 -> 9098.731 | D22: =Financials!M18 -> 10463.399 | E22: =Financials!N18 -> 11845.266 | F22: =Financials!O18 -> 13272.56 | G22: =Financials!P18 -> 14752.511
B23: EBIT | C23: =Financials!L19 -> 5564.6626 | D23: =Financials!M19 -> 5079.7982 | E23: =Financials!N19 -> 4785.9547 | F23: =Financials!O19 -> 4522.847 | G23: =Financials!P19 -> 4288.5736
B24: Less: taxes on EBIT | C24: =-C23*Assumptions!L15 -> -1574.7995 | D24: =-D23*Assumptions!M15 -> -1437.5829 | E24: =-E23*Assumptions!N15 -> -1354.4252 | F24: =-F23*Assumptions!O15 -> -1279.9657 | G24: =-G23*Assumptions!P15 -> -1213.6663
B25: NOPAT | C25: =C23+C24 -> 3989.8631 | D25: =D23+D24 -> 3642.2153 | E25: =E23+E24 -> 3431.5295 | F25: =F23+F24 -> 3242.8813 | G25: =G23+G24 -> 3074.9073
B26: Add: depreciation | C26: =C22 -> 9098.731 | D26: =D22 -> 10463.399 | E26: =E22 -> 11845.266 | F26: =F22 -> 13272.56 | G26: =G22 -> 14752.511
B27: Less: capital expenditure | C27: =Financials!L92 -> -26373.01 | D27: =Financials!M92 -> -27955.391 | E27: =Financials!N92 -> -29912.268 | F27: =Financials!O92 -> -32006.127 | G27: =Financials!P92 -> -34246.556
B28: Less: increase in working capital | C28: =SUM(Financials!L87:L90) -> 15.672243 | D28: =SUM(Financials!M87:M90) -> 37.977135 | E28: =SUM(Financials!N87:N90) -> 46.965056 | F28: =SUM(Financials!O87:O90) -> 50.25261 | G28: =SUM(Financials!P87:P90) -> 53.770293
B29: Unlevered free cash flow | C29: =C25+C26+C27+C28 -> -13268.744 | D29: =D25+D26+D27+D28 -> -13811.799 | E29: =E25+E26+E27+E28 -> -14588.507 | F29: =F25+F26+F27+F28 -> -15440.433 | G29: =G25+G26+G27+G28 -> -16365.367
B30: Discount period (years) | C30: 1 | D30: 2 | E30: 3 | F30: 4 | G30: 5
B31: Discount factor | C31: =1/(1+WACC!$C$16)^C30 -> 0.88823571 | D31: =1/(1+WACC!$C$16)^D30 -> 0.78896267 | E31: =1/(1+WACC!$C$16)^E30 -> 0.70078481 | F31: =1/(1+WACC!$C$16)^F30 -> 0.62246209 | G31: =1/(1+WACC!$C$16)^G30 -> 0.55289306
B32: PV of free cash flow | C32: =C29*C31 -> -11785.772 | D32: =D29*D31 -> -10896.994 | E32: =E29*E31 -> -10223.404 | F32: =F29*F31 -> -9611.0845 | G32: =G29*G31 -> -9048.2977
B35: Valuation
B36: Sum of PV of free cash flows | C36: =SUM(C32:G32) -> -51565.552
B37: Terminal value (normalised reinvestment, FY31E) | C37: =G25*(1+WACC!C17)*(1-WACC!C17/WACC!C18)/(WACC!C16-WACC!C17) -> 21289.516
B38: PV of terminal value | C38: =C37*G31 -> 11770.825
B39: Enterprise value | C39: =C36+C38 -> -39794.727
B40: Less: borrowings (FY26) | C40: =-Financials!K49 -> -106621.79
B41: Add: cash & bank (FY26) | C41: =Financials!K58 -> 11809.42
B42: Equity value | C42: =C39+C40+C41 -> -134607.1
B43: Shares outstanding (Cr) | C43: =Financials!K28 -> 129.16
B44: Implied value per share (₹) | C44: =C42/C43 -> -1042.1733
B45: Current market price (₹) | C45: 2668.9
B46: Upside / (downside) | C46: =C44/C45-1 -> -1.3904879
B48: Terminal value as % of EV | C48: =C38/C39 -> -0.29578857
B49: Implied terminal EV / EBITDA (x) | C49: =C37/G21 -> 1.1180831
B50: Equity value excludes minority interests (not separately reported in the source data). Shares = FY26 adjusted shares.
B53: Sensitivity: implied value per share (₹), WACC (down) vs terminal growth (across)
C54: =WACC!$C$17+(-0.01) -> 0.04 | D54: =WACC!$C$17+(-0.005) -> 0.045 | E54: =WACC!$C$17+(0) -> 0.05 | F54: =WACC!$C$17+(0.005) -> 0.055 | G54: =WACC!$C$17+(0.01) -> 0.06
B55: =WACC!$C$16+(-0.01) -> 0.11582729 | C55: =(SUMPRODUCT($C$29:$G$29,1/(1+$B55)^$C$30:$G$30)+$G$25*(1+C$54)*(1-C$54/WACC!$C$18)/($B55-C$54)/(1+$B55)^$G$30+$C$40+$C$41)/$C$43 -> -1030.43 | D55: =(SUMPRODUCT($C$29:$G$29,1/(1+$B55)^$C$30:$G$30)+$G$25*(1+D$54)*(1-D$54/WACC!$C$18)/($B55-D$54)/(1+$B55)^$G$30+$C$40+$C$41)/$C$43 -> -1032.0048 | E55: =(SUMPRODUCT($C$29:$G$29,1/(1+$B55)^$C$30:$G$30)+$G$25*(1+E$54)*(1-E$54/WACC!$C$18)/($B55-E$54)/(1+$B55)^$G$30+$C$40+$C$41)/$C$43 -> -1033.9233 | F55: =(SUMPRODUCT($C$29:$G$29,1/(1+$B55)^$C$30:$G$30)+$G$25*(1+F$54)*(1-F$54/WACC!$C$18)/($B55-F$54)/(1+$B55)^$G$30+$C$40+$C$41)/$C$43 -> -1036.2703 | G55: =(SUMPRODUCT($C$29:$G$29,1/(1+$B55)^$C$30:$G$30)+$G$25*(1+G$54)*(1-G$54/WACC!$C$18)/($B55-G$54)/(1+$B55)^$G$30+$C$40+$C$41)/$C$43 -> -1039.161
B56: =WACC!$C$16+(-0.005) -> 0.12082729 | C56: =(SUMPRODUCT($C$29:$G$29,1/(1+$B56)^$C$30:$G$30)+$G$25*(1+C$54)*(1-C$54/WACC!$C$18)/($B56-C$54)/(1+$B56)^$G$30+$C$40+$C$41)/$C$43 -> -1034.5406 | D56: =(SUMPRODUCT($C$29:$G$29,1/(1+$B56)^$C$30:$G$30)+$G$25*(1+D$54)*(1-D$54/WACC!$C$18)/($B56-D$54)/(1+$B56)^$G$30+$C$40+$C$41)/$C$43 -> -1036.4308 | E56: =(SUMPRODUCT($C$29:$G$29,1/(1+$B56)^$C$30:$G$30)+$G$25*(1+E$54)*(1-E$54/WACC!$C$18)/($B56-E$54)/(1+$B56)^$G$30+$C$40+$C$41)/$C$43 -> -1038.6828 | F56: =(SUMPRODUCT($C$29:$G$29,1/(1+$B56)^$C$30:$G$30)+$G$25*(1+F$54)*(1-F$54/WACC!$C$18)/($B56-F$54)/(1+$B56)^$G$30+$C$40+$C$41)/$C$43 -> -1041.3792 | G56: =(SUMPRODUCT($C$29:$G$29,1/(1+$B56)^$C$30:$G$30)+$G$25*(1+G$54)*(1-G$54/WACC!$C$18)/($B56-G$54)/(1+$B56)^$G$30+$C$40+$C$41)/$C$43 -> -1044.6295
B57: =WACC!$C$16+(0) -> 0.12582729 | C57: =(SUMPRODUCT($C$29:$G$29,1/(1+$B57)^$C$30:$G$30)+$G$25*(1+C$54)*(1-C$54/WACC!$C$18)/($B57-C$54)/(1+$B57)^$G$30+$C$40+$C$41)/$C$43 -> -1037.6086 | D57: =(SUMPRODUCT($C$29:$G$29,1/(1+$B57)^$C$30:$G$30)+$G$25*(1+D$54)*(1-D$54/WACC!$C$18)/($B57-D$54)/(1+$B57)^$G$30+$C$40+$C$41)/$C$43 -> -1039.709 | E57: =(SUMPRODUCT($C$29:$G$29,1/(1+$B57)^$C$30:$G$30)+$G$25*(1+E$54)*(1-E$54/WACC!$C$18)/($B57-E$54)/(1+$B57)^$G$30+$C$40+$C$41)/$C$43 -> -1042.1733 | F57: =(SUMPRODUCT($C$29:$G$29,1/(1+$B57)^$C$30:$G$30)+$G$25*(1+F$54)*(1-F$54/WACC!$C$18)/($B57-F$54)/(1+$B57)^$G$30+$C$40+$C$41)/$C$43 -> -1045.0783 | G57: =(SUMPRODUCT($C$29:$G$29,1/(1+$B57)^$C$30:$G$30)+$G$25*(1+G$54)*(1-G$54/WACC!$C$18)/($B57-G$54)/(1+$B57)^$G$30+$C$40+$C$41)/$C$43 -> -1048.5247
B58: =WACC!$C$16+(0.005) -> 0.13082729 | C58: =(SUMPRODUCT($C$29:$G$29,1/(1+$B58)^$C$30:$G$30)+$G$25*(1+C$54)*(1-C$54/WACC!$C$18)/($B58-C$54)/(1+$B58)^$G$30+$C$40+$C$41)/$C$43 -> -1039.8227 | D58: =(SUMPRODUCT($C$29:$G$29,1/(1+$B58)^$C$30:$G$30)+$G$25*(1+D$54)*(1-D$54/WACC!$C$18)/($B58-D$54)/(1+$B58)^$G$30+$C$40+$C$41)/$C$43 -> -1042.0576 | E58: =(SUMPRODUCT($C$29:$G$29,1/(1+$B58)^$C$30:$G$30)+$G$25*(1+E$54)*(1-E$54/WACC!$C$18)/($B58-E$54)/(1+$B58)^$G$30+$C$40+$C$41)/$C$43 -> -1044.6486 | F58: =(SUMPRODUCT($C$29:$G$29,1/(1+$B58)^$C$30:$G$30)+$G$25*(1+F$54)*(1-F$54/WACC!$C$18)/($B58-F$54)/(1+$B58)^$G$30+$C$40+$C$41)/$C$43 -> -1047.6662 | G58: =(SUMPRODUCT($C$29:$G$29,1/(1+$B58)^$C$30:$G$30)+$G$25*(1+G$54)*(1-G$54/WACC!$C$18)/($B58-G$54)/(1+$B58)^$G$30+$C$40+$C$41)/$C$43 -> -1051.2008
B59: =WACC!$C$16+(0.01) -> 0.13582729 | C59: =(SUMPRODUCT($C$29:$G$29,1/(1+$B59)^$C$30:$G$30)+$G$25*(1+C$54)*(1-C$54/WACC!$C$18)/($B59-C$54)/(1+$B59)^$G$30+$C$40+$C$41)/$C$43 -> -1041.3315 | D59: =(SUMPRODUCT($C$29:$G$29,1/(1+$B59)^$C$30:$G$30)+$G$25*(1+D$54)*(1-D$54/WACC!$C$18)/($B59-D$54)/(1+$B59)^$G$30+$C$40+$C$41)/$C$43 -> -1043.6458 | E59: =(SUMPRODUCT($C$29:$G$29,1/(1+$B59)^$C$30:$G$30)+$G$25*(1+E$54)*(1-E$54/WACC!$C$18)/($B59-E$54)/(1+$B59)^$G$30+$C$40+$C$41)/$C$43 -> -1046.3031 | F59: =(SUMPRODUCT($C$29:$G$29,1/(1+$B59)^$C$30:$G$30)+$G$25*(1+F$54)*(1-F$54/WACC!$C$18)/($B59-F$54)/(1+$B59)^$G$30+$C$40+$C$41)/$C$43 -> -1049.3671 | G59: =(SUMPRODUCT($C$29:$G$29,1/(1+$B59)^$C$30:$G$30)+$G$25*(1+G$54)*(1-G$54/WACC!$C$18)/($B59-G$54)/(1+$B59)^$G$30+$C$40+$C$41)/$C$43 -> -1052.9182
